<mujoco model="humanoid">

  <statistic extent="2" center="0 0 1"/>

  <option timestep="0.00555"/>

  <default>
    <motor ctrlrange="-1 1" ctrllimited="true"/>
    <default class="body">
      <geom  type="capsule" condim="1" friction="1.0 0.05 0.05" solimp=".9 .99 .003" solref=".015 1" material="self"/>
      <joint limited="true" type="hinge" damping="0.1" stiffness="5" armature=".007" solimplimit="0 .99 .01"/>
      <site size=".04" group="3"/>
      <default class="force-torque">
        <site type="box" size=".01 .01 .02" rgba="1 0 0 1" />
      </default>
      <default class="touch">
        <site type="capsule" rgba="0 0 1 .3"/>
      </default>
    </default>
  </default>

  <worldbody>
    <geom name="floor" type="plane" conaffinity="1" size="100 100 .2" material="grid"/>

    <body name="body" pos="1 1 1">
      <inertial mass="10" pos="0 0 0" diaginertia="0.1 0.1 0.1"/>
      <geom name="body" class="collision" type="box" size="0.42 0.11 0.08"/>

      <body name="body_link" pos="0.292 0 0.188" gravcomp="0.9">
        <!-- <joint name="link" class="link" type="hinge" axis="0 0 1" pos="0 0 0" range="-1000000 1000000" damping="10.0" armature=".01"/> -->
        <joint name="link" class="link" type="hinge" axis="0 0 1" pos="0 0 0" range="-200 45" damping="10.0" armature=".01"/>
        <!-- <joint name="link" class="link" type="hinge" axis="0 0 1" pos="0 0 0" range="-45 1000000" damping="10.0" armature=".01"/> -->
        <!-- <joint name="link" class="link" type="hinge" axis="0 0 1" pos="0 0 0" range="-4 3" damping="10.0" armature=".01"/> -->
        <!-- <joint name="link" class="link" type="hinge" axis="0 0 1" pos="0 0 0" range="-3 3" damping="10.0" armature=".01"/> -->
        <!-- <joint name="link" class="link" type="hinge" axis="0 0 1" pos="0 0 0" range="-1 1" damping="10.0" armature=".01"/> -->
        <inertial mass="1" diaginertia="0.1 0.1 0.1" pos="-0.008399 0.000272 -0.024603" />
        <geom name="geom_0" class="collision" type="capsule" size="0.05 0.015" pos="0 0 -0.07"/>
        <geom name="geom_1" class="collision" type="capsule" fromto="-0.015 -0.062 0 -0.015 0.062 0" size="0.05"/>
      </body>
    </body>
  </worldbody>


</mujoco>

